Workbook

Sheet ReadMe
B1: Oman Climate Transition Stress Test | v4 | Sector-level stressed PD
B3: Scope | C3: Transition risk AND acute physical risk, both expressed through stressed PD. Output is a stressed PD by sector and master rating grade for four NGFS scenarios. No customer or ECL layer. No LGD. Chronic physical risk through the macro channel is NOT included: see the scope note below.
B5: Core formula | C5: stressed_PD = NORMSDIST( NORMSINV(PD_0) + push + macro_shift )
C6: push = k x LN(1 + cost_ratio); cost_ratio = carbon price x deflator x intensity x intensity_index x (1 - pass_through) / (1,000,000 x GVA_index)
C7: macro_shift = beta x GDP_level_deviation x macro_beta_sector
C8: Pure probit shift. Returns PD_0 exactly at zero stress, so no de-stress artefact is possible. Asset correlation rho does not appear.
B10: Sector taxonomy | C10: The Verification tab records, for every input number, what it was checked against and what the check found. Quality_Checks then reports the live state of the model. Physical risk enters as a second cost ratio added to the carbon cost ratio inside the same push transform.
B12: Read this first | C12: The Verification tab records, for every input number, what it was checked against and what the check found. Four numbers changed as a result and three could not be verified from any public source. Quality_Checks then reports the live state of the model.
B14: Colour legend
B15: Blue font | C15: Bank input or editable assumption.
B16: Black font | C16: Live formula or verified constant.
B17: Green font | C17: Cross-sheet link.
B18: Yellow fill | C18: Unverified, placeholder, or requires a decision. Counted live on Quality_Checks.
B19: Lilac fill | C19: Illustrative sample, not used for calibration.

Sheet Change_Log
B1: What changed from v3 to v4
B4: # | C4: Area | D4: v3 | E4: v4
B5: 1 | C5: Output | D5: Customer-level ECL, aggregation and portfolio summary tabs. | E5: Removed entirely. The output is a sector by grade by scenario stressed PD grid, plus a PD-multiple summary at grade MR5.
B6: 2 | C6: Sector taxonomy | D6: 16 sectors, several built by splitting an SNA parent with a placeholder share, and two (real estate, water and waste) with no GVA at all, which meant they silently received no stress. | E6: 10 sectors. Every ISIC Rev.4 section sits in exactly one sector; every sector has a GVA figure taken from the source. No placeholder splits of GVA, no zero-GVA rows. ISIC L, E, N and R are not itemised in Oman's submission but the table still reconciles to published GDP, so they are absorbed into their parent sector rather than given empty rows.
B7: 3 | C7: ISIC B split | D7: 93% / 7% placeholder between oil and gas and other mining. | E7: Sourced. Oman's separately reported non-oil Mining GVA is 205.8 OMR m for 2023, so oil and gas extraction is 14,750.3 out of an ISIC B total of 14,956.1.
B8: 4 | C8: k anchor | D8: Two conflicting values, 2.0% to 2.05% and 2.0% to 4.0%, with the conflict flagged but unresolved. | E8: Both traced. 2.0% to 4.0% is COAL MINING under disorderly transition (OP 281 Section 5.4), not the median firm. 2.0% to 2.05% is the +2.5% relative disorderly-versus-orderly figure at 2050. The clean transition-only median-firm anchor is +0.5% relative, orderly versus hot house world in the policy implementation phase, and is now the default.
B9: 5 | C9: EU intensity | D9: 1,100 t/EURm revenue, described as a coal-mining figure. | E9: Identified as the LARGE-FIRM average on a Scope 1+2+3 basis, so neither median nor Scope 1. Replaced by a symmetric construction: EU national Scope 1 emissions divided by EU GVA, built exactly as the Oman intensity is, with a documented median-to-average adjustment.
B10: 6 | C10: Revenue versus GVA | D10: Flagged as a defect, handled by an unsourced turnover-to-GVA ratio applied to the EU anchor. | E10: Workaround implemented. Route 1 removes the conversion entirely by constructing both sides from national aggregates. Route 2 (the firm-level conversion) is retained for comparison, and a basis switch on Sector_Master lets the whole model run on turnover if the bank obtains it.
B11: 7 | C11: EU pass-through | D11: 50%. | E11: 0%. OP 281 Section 5.1 applies the carbon tax to operating costs with no cost relief; any demand response runs separately through Scope 3 revenues. There is no pass-through in the ECB cost channel.
B12: 8 | C12: Price base | D12: NGFS carbon prices in US$2010 applied directly to GVA in 2023 US dollars. | E12: US GDP deflator applied explicitly on Scenario_Mapping. Omitting it understated every cost ratio by roughly a quarter.
B13: 9 | C13: Carbon price value | D13: Net Zero 2035 at 290. | E13: Corrected to 294, per the NGFS Phase V statement that the price rises from $98/tCO2 in 2025 to $294/tCO2 by 2035.
B14: 10 | C14: Carbon price region | D14: Global, unremarked. | E14: Global, with the direction of bias documented: the NGFS footnote states prices tend to be LOWER in emerging economies, so applying the global path to Oman overstates the transition cost.
B15: 11 | C15: GVA vintage | D15: Undated. | E15: Identified as 2023 current prices, against 2024 EDGAR emissions. The one-year mismatch is disclosed and the 2024 replacement values are recorded in the Verification log.
... B24: 20 | C24: Ordering checks | D24: Transition ordering only. | E24: Both orderings now checked live. Transition must run NZ >= DT >= FW >= CP and physical must run CP >= FW >= DT >= NZ. Both pass.

Sheet Verification
B1: Verification log
B2: Every input number in the model, what it was checked against, and the result. VERIFIED means traced to the primary source named. CORRECTED means the source disagreed with the value in the workbook and the value has been changed. UNVERIFIABLE means no public source could confirm it and it remains a flagged input.
B4: # | C4: Value | D4: Value now in model | E4: Source checked against | F4: Finding | G4: Status
B5: 1 | C5: NGFS shadow carbon price, Net Zero 2050, 2035 | D5: US$2010 294 /tCO2 | E5: NGFS Phase V main report, Main results, Carbon prices | F5: The report states a price of about $300/tCO2 is needed by 2035 for net zero by 2050, rising from $98/tCO2 in 2025 to $294/tCO2. The workbook carried 290. Changed to 294. | G5: CORRECTED
B6: 2 | C6: Units of the NGFS carbon price | D6: US$2010 | E6: NGFS Phase V, Scenarios at a glance and Main results, chart axes | F6: Both carbon price charts are labelled US$2010 per tCO2. The workbook applied this directly to GVA measured in 2023 current US dollars. A price deflator is now applied explicitly on Scenario_Mapping. Omitting it understated every cost ratio by roughly a quarter. | G6: CORRECTED
B7: 3 | C7: Regional applicability of the carbon price | D7: Global weighted | E7: NGFS Phase V, Main results, Carbon prices, footnote | F7: The published prices are weighted global values. The footnote states that prices tend to be LOWER in emerging economies, because policy stringency is lower and more low-cost abatement remains available. Applying the global path to Oman therefore biases the transition cost UPWARDS. Country-downscaled prices exist in the IIASA portal for 220 countries. | G7: VERIFIED, conservative bias documented
B8: 4 | C8: End-of-century warming by scenario | D8: NZ 1.4, DT 1.7, FW 2.4, CP 3.0 | E8: NGFS Phase V, Scenarios at a glance | F8: All four match the source exactly. | G8: VERIFIED
B9: 5 | C9: Transition GDP deviation, Net Zero and Delayed Transition | D9: NZ -1.5 / -1.0 / -0.8; DT -0.3 / -2.0 / -1.7 | E9: NGFS Phase V GDP decomposition chart; ECB Occasional Paper 281 Section 3.2.1 | F9: The published Phase V chart gives the transition component graphically, not as a table, so exact values cannot be read off. The magnitudes and the shape (Net Zero loss peaks early then narrows, Delayed Transition loss appears around 2030 and peaks later) are consistent with the chart. ECB OP 281 independently states that the transition-risk impact is limited to no more than 2% of European GDP under a disorderly transition, which corroborates the -2.0% Delayed Transition figure. Values retained as plausible but not exact. | G9: PLAUSIBLE, not exact
B10: 6 | C10: Transition GDP deviation, Fragmented World | D10: 0.0 in every year | E10: NGFS Phase V GDP decomposition chart | F10: Fragmented World is NOT plotted in the published GDP decomposition chart, which shows only Net Zero 2050, Delayed Transition and Current Policies. No public figure exists. A zero deviation is not credible for a high-cost, badly co-ordinated transition. Requires the IIASA portal pull. | G10: UNVERIFIABLE - action required
B11: 7 | C11: Transition GDP deviation, Current Policies | D11: 0.0 in every year | E11: NGFS scenario design | F11: Correct by construction. Current Policies is the transition baseline and carries no additional transition cost. Its risk is physical, which this model does not cover. | G11: VERIFIED
B12: 8 | C12: EU anchor: median firm baseline PD | D12: 2.0% | E12: ECB Occasional Paper 281, Chart 31 panel b, right-hand axis | F12: The median-firm series on the right-hand axis runs from about 1.9% in 2020 to about 2.4% by 2050. A 2020 baseline of 2.0% is supported. | G12: VERIFIED
B13: 9 | C13: EU anchor: median firm PD response | D13: +0.5% RELATIVE (transition-only) | E13: ECB Occasional Paper 281, Section 5.3 | F13: Section 5.3 states the median firm would have a slightly higher PD, about 0.5%, under orderly transition during the policy implementation phase compared with the hot house world. Because hot house world carries no transition policy, this difference is a CLEAN transition-only effect. Chart 28 confirms these are percentage CHANGES relative to baseline, not percentage points. So 2.00% becomes 2.01%. | G13: VERIFIED and corrected
B14: 10 | C14: Origin of the 2.0% to 2.05% figure in the v2 sheet | D14: Not used as primary | E14: ECB Occasional Paper 281, Section 5.3 | F14: This is the +2.5% relative figure for DISORDERLY transition versus orderly at 2050. It is not the transition-only median-firm anchor and it mixes transition timing with residual physical effects. Retained as selectable Anchor B for sensitivity. | G14: IDENTIFIED
B15: 11 | C15: Origin of the 2.0% to 4.0% figure in the v2 register | D15: Not used | E15: ECB Occasional Paper 281, Section 5.4 and Chart 31 | F15: This is COAL MINING (NACE B05), not the median firm: the paper states the transition would drive coal-mining PDs to 5% and 4% under orderly and disorderly transition, a 150% and 100% increase on current values. The register entry was a coal-mining anchor mislabelled as a median-firm anchor. Discarded, because the user is calibrating on a median firm. | G15: RESOLVED
... B43: 39 | C43: Insurance recovery and P&L share | D43: 25% recovery, 60% of retained loss to P&L | E43: Analyst judgement | F43: Oman's non-life insurance penetration is low and catastrophe cover is not universal. The 60/40 split between P&L impact and capital replacement is what keeps the PD and LGD channels from double counting the same damage. | G43: JUDGEMENT

Sheet Quality_Checks
B1: Quality checks (live)
B2: Every check is a live formula. Items marked ACTION are decisions or data pulls that only the bank or a source download can resolve; they are deliberately left visible rather than defaulted away.
B4: # | C4: Check | D4: Result | E4: Status | F4: What it means
B5: 1 | C5: Sector GVA reconciles to SNA total value added | D5: =Sector_Master!E18 -> 41963.907 | E5: =Sector_Master!E20 -> PASS | F5: Sector GVA must equal 41,963.9 OMR m exactly. Every ISIC section is in exactly one sector.
B6: 2 | C6: Every EDGAR row's allocation shares sum to 1.00 | D6: =COUNTIF(Emissions_Allocation!R6:R12,"FAIL") -> 0 | E6: =IF(D6=0,"PASS","FAIL") -> PASS | F6: Fix the shaded share cells on Emissions_Allocation.
B7: 3 | C7: EDGAR categories reconcile to the national total | D7: =Emissions_Allocation!D15 -> PASS | E7: =Emissions_Allocation!D15 -> PASS | F7: The E7 residual is a plug, so this holds unless the national total is edited.
B8: 4 | C8: Allocated sector emissions reconcile to the national total | D8: =Emissions_Allocation!R17 -> OK | E8: =Emissions_Allocation!R17 -> OK | F8: Allocation has neither lost nor created emissions.
B9: 5 | C9: Sectors with zero computed intensity | D9: =COUNTIF(Oman_Intensity!F6:F15,0) -> 0 | E9: =IF(D9=0,"PASS","FAIL") -> PASS | F9: Must be zero. This was the v3 defect: rows were created for ISIC sections Oman does not itemise, so those sectors had no denominator and received no stress. The v4 taxonomy makes it structurally impossible.
B10: 6 | C10: No de-stress: stressed PD is never below baseline | D10: =StressedPD_Sector!G100 -> 0 | E10: =IF(D10=0,"PASS","FAIL") -> PASS | F10: Under the probit-shift form this can only fail if a push or macro shift is negative.
B11: 7 | C11: Probit identity: NORMSDIST(NORMSINV(2%)) = 2% | D11: =StressedPD_Sector!G101 -> 0.02 | E11: =IF(ABS(D11-0.02)<0.000000001,"PASS","FAIL") -> PASS | F11: Confirms the transform round-trips and the baseline is preserved at zero stress.
B12: 8 | C12: Sectors where physical cost exceeds transition cost under Current Policies | D12: =SUMPRODUCT((StressedPD_Sector!M16:M25>StressedPD_Sector!I16:I25)*1) -> 7 | E12: =IF(D12>0,"crossover present","no crossover") -> crossover present | F12: Diagnostic, not a pass or fail. Current Policies has almost no transition cost by construction, so physical damage should dominate there. If this reads zero at a long horizon, the physical module is switched off or mis-scaled. Ordering itself is tested separately by checks 22 and 23.
B13: 9 | C13: Denominator basis in use | D13: =Sector_Master!C4 -> GVA | E13: =IF(Sector_Master!C4="GVA","GVA","TURNOVER") -> GVA | F13: GVA by default, because Oman publishes value added by activity but not turnover. The EU anchor is converted onto the same basis on EU_k_Calibration rather than left as an implicit unit mismatch.
B14: 10 | C14: EU intensity route in use | D14: =EU_k_Calibration!C34 -> 1 | E14: =IF(D14=1,"Symmetric","Firm-level") -> Symmetric | F14: Route 1 (symmetric) builds the EU intensity the same way the Oman intensity is built, national Scope 1 emissions over national GVA, so the turnover conversion never enters.
B15: 11 | C15: US GDP deflator applied to the carbon price | D15: =Scenario_Mapping!C15 -> 1.35 | E15: =IF(D15>1.01,"PASS","FAIL") -> PASS | F15: NGFS prices are US$2010; the denominator is 2023 US dollars. v2 mixed the two, understating every cost ratio by roughly a quarter.
B16: 12 | C16: Corporate share of national emissions | D16: =Emissions_Allocation!D26 -> 0.8169275 | E16: =IF(AND(D16>0.4,D16<0.9),"PASS","REVIEW") -> PASS | F16: The remainder is households and own-account use. If this drifts above 90% the household exclusion has been switched off and private vehicle and residential emissions are being charged to borrowers.
B17: 13 | C17: Live regression reproduces the reported slope | D17: =ABS(Regression_Data!E19-Macro_Shift!C5) -> 0 | E17: =IF(D17<0.00001,"PASS","FAIL") -> PASS | F17: The estimation on Regression_Data must reproduce the selected specification on Regression_Tests.
B18: 14 | C18: EDGAR Buildings emissions per head (tCO2e) | D18: =Emissions_Allocation!D23 -> 4.1943396 | E18: =IF(D18<3,"PASS","FLAG") -> FLAG | F18: EXPECTED TO FLAG. This is direct building fuel combustion only, since air conditioning electricity is already under Power Industry. Above about 3 tCO2e per head the figure is not credible for a hot climate. Seventy per cent is allocated to households so it does not distort corporate intensities, but re-download the EDGAR sector file.
B19: 15 | C19: Fragmented World carries a non-zero GDP deviation | D19: =Scenario_Mapping!D25 -> ACTION - FW deviation is zero in every year | E19: =IF(LEFT(D19,4)="PASS","PASS","ACTION") -> ACTION | F19: EXPECTED TO SHOW ACTION. Fragmented World is not plotted in the published NGFS chart and no public figure exists, but a zero deviation for a high-cost, badly co-ordinated transition is not credible. Requires the IIASA portal pull.
B20: 16 | C20: k anchor decision recorded | D20: =EU_k_Calibration!C8 -> A | E20: =IF(D20="A","Anchor A (transition-only, +0.5% relative)","Anchor B (disorderly 2050, +2.5% relative)") -> Anchor A (transition-only, +0.5% relative) | F20: Both are now traced to ECB OP 281 Section 5.3. Anchor A is the default because it is the only clean transition-only identification.
B21: 17 | C21: Extrapolation multiple of k beyond its calibration point | D21: =EU_k_Calibration!C68 -> 129.70533 | E21: =IF(D21<10,"PASS","DISCLOSE") -> DISCLOSE | F21: k is calibrated at one cost ratio and applied far above it. Above 10x, disclose or cap.
B22: 18 | C22: Curvature parameter theta in use | D22: =k_MultiAnchor!C17 -> 0 | E22: =IF(D22=0,"log (v4 default)","non-default") -> log (v4 default) | F22: theta = 0 is the logarithmic form. The ECB anchors cannot identify this parameter (see k_MultiAnchor section C); it is exposed so the range can be reported rather than assumed away.
B23: 19 | C23: Coal anchor out-of-sample check | D23: =k_MultiAnchor!C40 -> 47.45908 | E23: =IF(D23<3,"consistent","REJECTED") -> REJECTED | F23: EXPECTED TO REJECT. The coal-mining PD response demands an intensity 20 to 50 times higher than coal plausibly has on a Scope 1 basis, confirming OP 281's own statement that the response is driven by Scope 3 abatement investment raising leverage. It therefore cannot calibrate a Scope 1 cost curve.
B24: 20 | C24: Cost ratio cap and cells bound | D24: =k_MultiAnchor!C61 -> 0 | E24: =IF(k_MultiAnchor!C60>100,"OFF","ON") -> OFF | F24: Wired but off. Given that curvature cannot be estimated above the calibration range, a cap is the only mechanism that bounds the utilities and manufacturing result. Set k_MultiAnchor C60 to switch it on.
B25: 21 | C25: Physical exposure weights normalise to 1.00 | D25: =Physical_Exposure!H18 -> PASS | E25: =IF(D25="PASS","PASS","FAIL") -> PASS | F25: Exposure weights redistribute the national annual average loss across sectors; they must not change its total. The value-added-weighted mean of the normalised weights must be exactly 1.000 for all three hazards.
B26: 22 | C26: Transition ordering: NZ >= DT >= FW >= CP | D26: =StressedPD_Sector!G102 -> 0 | E26: =IF(D26=0,"PASS","FAIL") -> PASS | F26: Transition severity must follow the carbon price ordering.
B27: 23 | C27: Physical ordering: CP >= FW >= DT >= NZ | D27: =StressedPD_Sector!G103 -> 0 | E27: =IF(D27=0,"PASS","FAIL") -> PASS | F27: Physical severity must follow the warming ordering, i.e. the exact reverse of transition. If both pass, the model has internally coherent opposing channels, which is the single most important structural test of a climate scenario model.
B28: 24 | C28: Warming path at horizon is interpolated, not sourced | D28: =Physical_Hazard!E34 -> 1.64 | E28: =IF(Physical_Hazard!D30>0,"FLAG","FLAG") -> FLAG | F28: EXPECTED TO FLAG. The warming figure at the horizon is a straight-line interpolation between today and 2100. Replace with the MAGICC temperature path published with NGFS Phase V. This is the weakest input in the physical module.
C30: Count of FAIL / ACTION / FLAG / REJECTED | E30: =COUNTIF(E5:E28,"FAIL")+COUNTIF(E5:E28,"ACTION")+COUNTIF(E5:E28,"FLAG")+COUNTIF(E5:E28,"REJECTED") -> 4
C32: Four items are expected to flag on delivery: 14 (EDGAR Buildings), 15 (Fragmented World transition deviation), 19 (the coal anchor, an intended diagnostic) and 24 (the warming interpolation).

Sheet StressedPD_Sector
B1: Stressed PD by sector and rating grade [MAIN OUTPUT]
B2: stressed_PD = NORMSDIST( NORMSINV(PD_0) + push + macro_shift ), where push = k x g(transition cost ratio + physical cost ratio). The two cost ratios are added INSIDE the transform, not as two separate pushes, because the transform is concave: adding two separate pushes would understate the joint effect of facing both shocks at once.
B4: Horizon year | C4: =Scenario_Mapping!C39 -> 2040
B5: k (fitted on ECB anchor 1) | C5: =k_MultiAnchor!C20 -> 0.26300976
B6: US GDP deflator, 2010 to denominator base | C6: =Scenario_Mapping!C15 -> 1.35
B7: Curvature parameter theta | C7: =k_MultiAnchor!C17 -> 0
C8: Net Zero 2050 | D8: Delayed Transition | E8: Current Policies | F8: Fragmented World
B9: Carbon price at horizon (US$2010/tCO2) | C9: =INDEX(NGFS_CarbonPrice!$C$6:$F$9,MATCH(C$8,NGFS_CarbonPrice!$B$6:$B$9,0),MATCH($C$4,NGFS_CarbonPrice!$C$5:$F$5,0)) -> 420 | D9: =INDEX(NGFS_CarbonPrice!$C$6:$F$9,MATCH(D$8,NGFS_CarbonPrice!$B$6:$B$9,0),MATCH($C$4,NGFS_CarbonPrice!$C$5:$F$5,0)) -> 165 | E9: =INDEX(NGFS_CarbonPrice!$C$6:$F$9,MATCH(E$8,NGFS_CarbonPrice!$B$6:$B$9,0),MATCH($C$4,NGFS_CarbonPrice!$C$5:$F$5,0)) -> 8 | F9: =INDEX(NGFS_CarbonPrice!$C$6:$F$9,MATCH(F$8,NGFS_CarbonPrice!$B$6:$B$9,0),MATCH($C$4,NGFS_CarbonPrice!$C$5:$F$5,0)) -> 35
B10: Carbon price deflated | C10: =C9*$C$6 -> 567 | D10: =D9*$C$6 -> 222.75 | E10: =E9*$C$6 -> 10.8 | F10: =F9*$C$6 -> 47.25
B11: Emissions intensity index | C11: =INDEX(Dynamic_Adjust!$C$6:$C$9,MATCH(C$8,Dynamic_Adjust!$B$6:$B$9,0)) -> 1 | D11: =INDEX(Dynamic_Adjust!$C$6:$C$9,MATCH(D$8,Dynamic_Adjust!$B$6:$B$9,0)) -> 1 | E11: =INDEX(Dynamic_Adjust!$C$6:$C$9,MATCH(E$8,Dynamic_Adjust!$B$6:$B$9,0)) -> 1 | F11: =INDEX(Dynamic_Adjust!$C$6:$C$9,MATCH(F$8,Dynamic_Adjust!$B$6:$B$9,0)) -> 1
B12: Denominator index | C12: =INDEX(Dynamic_Adjust!$D$6:$D$9,MATCH(C$8,Dynamic_Adjust!$B$6:$B$9,0)) -> 1 | D12: =INDEX(Dynamic_Adjust!$D$6:$D$9,MATCH(D$8,Dynamic_Adjust!$B$6:$B$9,0)) -> 1 | E12: =INDEX(Dynamic_Adjust!$D$6:$D$9,MATCH(E$8,Dynamic_Adjust!$B$6:$B$9,0)) -> 1 | F12: =INDEX(Dynamic_Adjust!$D$6:$D$9,MATCH(F$8,Dynamic_Adjust!$B$6:$B$9,0)) -> 1
B13: macro_shift before macro_beta | C13: =INDEX(Macro_Shift!$E$15:$E$18,MATCH(C$8,Macro_Shift!$B$15:$B$18,0)) -> 0.0095201194 | D13: =INDEX(Macro_Shift!$E$15:$E$18,MATCH(D$8,Macro_Shift!$B$15:$B$18,0)) -> 0.019040239 | E13: =INDEX(Macro_Shift!$E$15:$E$18,MATCH(E$8,Macro_Shift!$B$15:$B$18,0)) -> 0 | F13: =INDEX(Macro_Shift!$E$15:$E$18,MATCH(F$8,Macro_Shift!$B$15:$B$18,0)) -> 0
B15: ID | C15: Sector | D15: Intensity (t/US$m) | E15: Pass-through | F15: macro_beta | G15: transition NZ | H15: transition DT | I15: transition CP | J15: transition FW | K15: physical NZ | L15: physical DT | M15: physical CP | N15: physical FW | O15: TOTAL cost NZ | P15: TOTAL cost DT | Q15: TOTAL cost CP | R15: TOTAL cost FW | S15: push NZ | T15: push DT | U15: push CP | V15: push FW | W15: macro NZ | X15: macro DT | Y15: macro CP | Z15: macro FW
B16: S01 | C16: Agriculture, Forestry & Fishing | D16: =Oman_Intensity!F6 -> 717.44975 | E16: =Oman_Intensity!G6 -> 0.25 | F16: =Oman_Intensity!H6 -> 1 | G16: =IF($D16<=0,0,C$10*$D16*C$11*(1-$E16)/(1000000*C$12)) -> 0.30509551 | H16: =IF($D16<=0,0,D$10*$D16*D$11*(1-$E16)/(1000000*D$12)) -> 0.11985895 | I16: =IF($D16<=0,0,E$10*$D16*E$11*(1-$E16)/(1000000*E$12)) -> 0.005811343 | J16: =IF($D16<=0,0,F$10*$D16*F$11*(1-$E16)/(1000000*F$12)) -> 0.025424626 | K16: =Physical_Exposure!D25 -> 0.016476475 | L16: =Physical_Exposure!E25 -> 0.01828231 | M16: =Physical_Exposure!F25 -> 0.027614921 | N16: =Physical_Exposure!G25 -> 0.022991798 | O16: =MIN(G16+K16,k_MultiAnchor!$C$60) -> 0.32157198 | P16: =MIN(H16+L16,k_MultiAnchor!$C$60) -> 0.13814126 | Q16: =MIN(I16+M16,k_MultiAnchor!$C$60) -> 0.033426264 | R16: =MIN(J16+N16,k_MultiAnchor!$C$60) -> 0.048416423 | S16: =$C$5*IF(ABS($C$7)<0.000000000001,LN(1+O16),((1+O16)^$C$7-1)/$C$7) -> 0.073332888 | T16: =$C$5*IF(ABS($C$7)<0.000000000001,LN(1+P16),((1+P16)^$C$7-1)/$C$7) -> 0.034032531 | U16: =$C$5*IF(ABS($C$7)<0.000000000001,LN(1+Q16),((1+Q16)^$C$7-1)/$C$7) -> 0.0086476958 | V16: =$C$5*IF(ABS($C$7)<0.000000000001,LN(1+R16),((1+R16)^$C$7-1)/$C$7) -> 0.012435327 | W16: =C$13*$F16 -> 0.0095201194 | X16: =D$13*$F16 -> 0.019040239 | Y16: =E$13*$F16 -> 0 | Z16: =F$13*$F16 -> 0
B17: S02 | C17: Oil & Gas Extraction | D17: =Oman_Intensity!F7 -> 1185.1007 | E17: =Oman_Intensity!G7 -> 0.05 | F17: =Oman_Intensity!H7 -> 1 | G17: =IF($D17<=0,0,C$10*$D17*C$11*(1-$E17)/(1000000*C$12)) -> 0.63835448 | H17: =IF($D17<=0,0,D$10*$D17*D$11*(1-$E17)/(1000000*D$12)) -> 0.25078212 | I17: =IF($D17<=0,0,E$10*$D17*E$11*(1-$E17)/(1000000*E$12)) -> 0.012159133 | J17: =IF($D17<=0,0,F$10*$D17*F$11*(1-$E17)/(1000000*F$12)) -> 0.053196207 | K17: =Physical_Exposure!D26 -> 0.0064994814 | L17: =Physical_Exposure!E26 -> 0.0072663239 | M17: =Physical_Exposure!F26 -> 0.01129257 | N17: =Physical_Exposure!G26 -> 0.0092865145 | O17: =MIN(G17+K17,k_MultiAnchor!$C$60) -> 0.64485396 | P17: =MIN(H17+L17,k_MultiAnchor!$C$60) -> 0.25804844 | Q17: =MIN(I17+M17,k_MultiAnchor!$C$60) -> 0.023451703 | R17: =MIN(J17+N17,k_MultiAnchor!$C$60) -> 0.062482721 | S17: =$C$5*IF(ABS($C$7)<0.000000000001,LN(1+O17),((1+O17)^$C$7-1)/$C$7) -> 0.13088723 | T17: =$C$5*IF(ABS($C$7)<0.000000000001,LN(1+P17),((1+P17)^$C$7-1)/$C$7) -> 0.060376958 | U17: =$C$5*IF(ABS($C$7)<0.000000000001,LN(1+Q17),((1+Q17)^$C$7-1)/$C$7) -> 0.0060968127 | V17: =$C$5*IF(ABS($C$7)<0.000000000001,LN(1+R17),((1+R17)^$C$7-1)/$C$7) -> 0.01594059 | W17: =C$13*$F17 -> 0.0095201194 | X17: =D$13*$F17 -> 0.019040239 | Y17: =E$13*$F17 -> 0 | Z17: =F$13*$F17 -> 0
B18: S03 | C18: Mining & Quarrying (non-oil) | D18: =Oman_Intensity!F8 -> 1334.9036 | E18: =Oman_Intensity!G8 -> 0.3 | F18: =Oman_Intensity!H8 -> 1 | G18: =IF($D18<=0,0,C$10*$D18*C$11*(1-$E18)/(1000000*C$12)) -> 0.52982324 | H18: =IF($D18<=0,0,D$10*$D18*D$11*(1-$E18)/(1000000*D$12)) -> 0.20814484 | I18: =IF($D18<=0,0,E$10*$D18*E$11*(1-$E18)/(1000000*E$12)) -> 0.010091871 | J18: =IF($D18<=0,0,F$10*$D18*F$11*(1-$E18)/(1000000*F$12)) -> 0.044151937 | K18: =Physical_Exposure!D27 -> 0.010911436 | L18: =Physical_Exposure!E27 -> 0.012289413 | M18: =Physical_Exposure!F27 -> 0.019616425 | N18: =Physical_Exposure!G27 -> 0.015949272 | O18: =MIN(G18+K18,k_MultiAnchor!$C$60) -> 0.54073468 | P18: =MIN(H18+L18,k_MultiAnchor!$C$60) -> 0.22043426 | Q18: =MIN(I18+M18,k_MultiAnchor!$C$60) -> 0.029708296 | R18: =MIN(J18+N18,k_MultiAnchor!$C$60) -> 0.060101209 | S18: =$C$5*IF(ABS($C$7)<0.000000000001,LN(1+O18),((1+O18)^$C$7-1)/$C$7) -> 0.11368843 | T18: =$C$5*IF(ABS($C$7)<0.000000000001,LN(1+P18),((1+P18)^$C$7-1)/$C$7) -> 0.052393318 | U18: =$C$5*IF(ABS($C$7)<0.000000000001,LN(1+Q18),((1+Q18)^$C$7-1)/$C$7) -> 0.0076997566 | V18: =$C$5*IF(ABS($C$7)<0.000000000001,LN(1+R18),((1+R18)^$C$7-1)/$C$7) -> 0.015350403 | W18: =C$13*$F18 -> 0.0095201194 | X18: =D$13*$F18 -> 0.019040239 | Y18: =E$13*$F18 -> 0 | Z18: =F$13*$F18 -> 0
B19: S04 | C19: Manufacturing | D19: =Oman_Intensity!F9 -> 2087.9448 | E19: =Oman_Intensity!G9 -> 0.3 | F19: =Oman_Intensity!H9 -> 1 | G19: =IF($D19<=0,0,C$10*$D19*C$11*(1-$E19)/(1000000*C$12)) -> 0.82870529 | H19: =IF($D19<=0,0,D$10*$D19*D$11*(1-$E19)/(1000000*D$12)) -> 0.32556279 | I19: =IF($D19<=0,0,E$10*$D19*E$11*(1-$E19)/(1000000*E$12)) -> 0.015784863 | J19: =IF($D19<=0,0,F$10*$D19*F$11*(1-$E19)/(1000000*F$12)) -> 0.069058774 | K19: =Physical_Exposure!D28 -> 0.0064242651 | L19: =Physical_Exposure!E28 -> 0.0071248132 | M19: =Physical_Exposure!F28 -> 0.010722697 | N19: =Physical_Exposure!G28 -> 0.00894478 | O19: =MIN(G19+K19,k_MultiAnchor!$C$60) -> 0.83512955 | P19: =MIN(H19+L19,k_MultiAnchor!$C$60) -> 0.33268761 | Q19: =MIN(I19+M19,k_MultiAnchor!$C$60) -> 0.02650756 | R19: =MIN(J19+N19,k_MultiAnchor!$C$60) -> 0.078003554 | S19: =$C$5*IF(ABS($C$7)<0.000000000001,LN(1+O19),((1+O19)^$C$7-1)/$C$7) -> 0.15967719 | T19: =$C$5*IF(ABS($C$7)<0.000000000001,LN(1+P19),((1+P19)^$C$7-1)/$C$7) -> 0.075535788 | U19: =$C$5*IF(ABS($C$7)<0.000000000001,LN(1+Q19),((1+Q19)^$C$7-1)/$C$7) -> 0.006880946 | V19: =$C$5*IF(ABS($C$7)<0.000000000001,LN(1+R19),((1+R19)^$C$7-1)/$C$7) -> 0.019754866 | W19: =C$13*$F19 -> 0.0095201194 | X19: =D$13*$F19 -> 0.019040239 | Y19: =E$13*$F19 -> 0 | Z19: =F$13*$F19 -> 0
B20: S05 | C20: Electricity, Gas, Water & Waste | D20: =Oman_Intensity!F10 -> 8926.9692 | E20: =Oman_Intensity!G10 -> 0.8 | F20: =Oman_Intensity!H10 -> 1 | G20: =IF($D20<=0,0,C$10*$D20*C$11*(1-$E20)/(1000000*C$12)) -> 1.0123183 | H20: =IF($D20<=0,0,D$10*$D20*D$11*(1-$E20)/(1000000*D$12)) -> 0.39769648 | I20: =IF($D20<=0,0,E$10*$D20*E$11*(1-$E20)/(1000000*E$12)) -> 0.019282253 | J20: =IF($D20<=0,0,F$10*$D20*F$11*(1-$E20)/(1000000*F$12)) -> 0.084359859 | K20: =Physical_Exposure!D29 -> 0.0080605421 | L20: =Physical_Exposure!E29 -> 0.0089195449 | M20: =Physical_Exposure!F29 -> 0.013315013 | N20: =Physical_Exposure!G29 -> 0.011145856 | O20: =MIN(G20+K20,k_MultiAnchor!$C$60) -> 1.0203788 | P20: =MIN(H20+L20,k_MultiAnchor!$C$60) -> 0.40661602 | Q20: =MIN(I20+M20,k_MultiAnchor!$C$60) -> 0.032597266 | R20: =MIN(J20+N20,k_MultiAnchor!$C$60) -> 0.095505715 | S20: =$C$5*IF(ABS($C$7)<0.000000000001,LN(1+O20),((1+O20)^$C$7-1)/$C$7) -> 0.18497083 | T20: =$C$5*IF(ABS($C$7)<0.000000000001,LN(1+P20),((1+P20)^$C$7-1)/$C$7) -> 0.089735468 | U20: =$C$5*IF(ABS($C$7)<0.000000000001,LN(1+Q20),((1+Q20)^$C$7-1)/$C$7) -> 0.0084366288 | V20: =$C$5*IF(ABS($C$7)<0.000000000001,LN(1+R20),((1+R20)^$C$7-1)/$C$7) -> 0.023990724 | W20: =C$13*$F20 -> 0.0095201194 | X20: =D$13*$F20 -> 0.019040239 | Y20: =E$13*$F20 -> 0 | Z20: =F$13*$F20 -> 0
B21: S06 | C21: Construction | D21: =Oman_Intensity!F11 -> 198.61822 | E21: =Oman_Intensity!G11 -> 0.5 | F21: =Oman_Intensity!H11 -> 1 | G21: =IF($D21<=0,0,C$10*$D21*C$11*(1-$E21)/(1000000*C$12)) -> 0.056308264 | H21: =IF($D21<=0,0,D$10*$D21*D$11*(1-$E21)/(1000000*D$12)) -> 0.022121104 | I21: =IF($D21<=0,0,E$10*$D21*E$11*(1-$E21)/(1000000*E$12)) -> 0.0010725384 | J21: =IF($D21<=0,0,F$10*$D21*F$11*(1-$E21)/(1000000*F$12)) -> 0.0046923554 | K21: =Physical_Exposure!D30 -> 0.012126552 | L21: =Physical_Exposure!E30 -> 0.013702392 | M21: =Physical_Exposure!F30 -> 0.022114953 | N21: =Physical_Exposure!G30 -> 0.017898683 | O21: =MIN(G21+K21,k_MultiAnchor!$C$60) -> 0.068434816 | P21: =MIN(H21+L21,k_MultiAnchor!$C$60) -> 0.035823496 | Q21: =MIN(I21+M21,k_MultiAnchor!$C$60) -> 0.023187491 | R21: =MIN(J21+N21,k_MultiAnchor!$C$60) -> 0.022591038 | S21: =$C$5*IF(ABS($C$7)<0.000000000001,LN(1+O21),((1+O21)^$C$7-1)/$C$7) -> 0.017409876 | T21: =$C$5*IF(ABS($C$7)<0.000000000001,LN(1+P21),((1+P21)^$C$7-1)/$C$7) -> 0.0092570911 | U21: =$C$5*IF(ABS($C$7)<0.000000000001,LN(1+Q21),((1+Q21)^$C$7-1)/$C$7) -> 0.006028906 | V21: =$C$5*IF(ABS($C$7)<0.000000000001,LN(1+R21),((1+R21)^$C$7-1)/$C$7) -> 0.0058755434 | W21: =C$13*$F21 -> 0.0095201194 | X21: =D$13*$F21 -> 0.019040239 | Y21: =E$13*$F21 -> 0 | Z21: =F$13*$F21 -> 0
B22: S07 | C22: Wholesale & Retail Trade | D22: =Oman_Intensity!F12 -> 428.01663 | E22: =Oman_Intensity!G12 -> 0.7 | F22: =Oman_Intensity!H12 -> 1 | G22: =IF($D22<=0,0,C$10*$D22*C$11*(1-$E22)/(1000000*C$12)) -> 0.072805628 | H22: =IF($D22<=0,0,D$10*$D22*D$11*(1-$E22)/(1000000*D$12)) -> 0.028602211 | I22: =IF($D22<=0,0,E$10*$D22*E$11*(1-$E22)/(1000000*E$12)) -> 0.0013867739 | J22: =IF($D22<=0,0,F$10*$D22*F$11*(1-$E22)/(1000000*F$12)) -> 0.0060671357 | K22: =Physical_Exposure!D31 -> 0.0037660892 | L22: =Physical_Exposure!E31 -> 0.0041781021 | M22: =Physical_Exposure!F31 -> 0.0062840799 | N22: =Physical_Exposure!G31 -> 0.005245403 | O22: =MIN(G22+K22,k_MultiAnchor!$C$60) -> 0.076571717 | P22: =MIN(H22+L22,k_MultiAnchor!$C$60) -> 0.032780313 | Q22: =MIN(I22+M22,k_MultiAnchor!$C$60) -> 0.0076708537 | R22: =MIN(J22+N22,k_MultiAnchor!$C$60) -> 0.011312539 | S22: =$C$5*IF(ABS($C$7)<0.000000000001,LN(1+O22),((1+O22)^$C$7-1)/$C$7) -> 0.019405296 | T22: =$C$5*IF(ABS($C$7)<0.000000000001,LN(1+P22),((1+P22)^$C$7-1)/$C$7) -> 0.008483248 | U22: =$C$5*IF(ABS($C$7)<0.000000000001,LN(1+Q22),((1+Q22)^$C$7-1)/$C$7) -> 0.0020098107 | V22: =$C$5*IF(ABS($C$7)<0.000000000001,LN(1+R22),((1+R22)^$C$7-1)/$C$7) -> 0.0029586048 | W22: =C$13*$F22 -> 0.0095201194 | X22: =D$13*$F22 -> 0.019040239 | Y22: =E$13*$F22 -> 0 | Z22: =F$13*$F22 -> 0
B23: S08 | C23: Transport & Storage | D23: =Oman_Intensity!F13 -> 1190.4402 | E23: =Oman_Intensity!G13 -> 0.6 | F23: =Oman_Intensity!H13 -> 1 | G23: =IF($D23<=0,0,C$10*$D23*C$11*(1-$E23)/(1000000*C$12)) -> 0.26999184 | H23: =IF($D23<=0,0,D$10*$D23*D$11*(1-$E23)/(1000000*D$12)) -> 0.10606822 | I23: =IF($D23<=0,0,E$10*$D23*E$11*(1-$E23)/(1000000*E$12)) -> 0.0051427016 | J23: =IF($D23<=0,0,F$10*$D23*F$11*(1-$E23)/(1000000*F$12)) -> 0.02249932 | K23: =Physical_Exposure!D32 -> 0.0067073924 | L23: =Physical_Exposure!E32 -> 0.0075268282 | M23: =Physical_Exposure!F32 -> 0.011833316 | N23: =Physical_Exposure!G32 -> 0.0096872415 | O23: =MIN(G23+K23,k_MultiAnchor!$C$60) -> 0.27669923 | P23: =MIN(H23+L23,k_MultiAnchor!$C$60) -> 0.11359505 | Q23: =MIN(I23+M23,k_MultiAnchor!$C$60) -> 0.016976018 | R23: =MIN(J23+N23,k_MultiAnchor!$C$60) -> 0.032186561 | S23: =$C$5*IF(ABS($C$7)<0.000000000001,LN(1+O23),((1+O23)^$C$7-1)/$C$7) -> 0.064247503 | T23: =$C$5*IF(ABS($C$7)<0.000000000001,LN(1+P23),((1+P23)^$C$7-1)/$C$7) -> 0.028298158 | U23: =$C$5*IF(ABS($C$7)<0.000000000001,LN(1+Q23),((1+Q23)^$C$7-1)/$C$7) -> 0.0044273842 | V23: =$C$5*IF(ABS($C$7)<0.000000000001,LN(1+R23),((1+R23)^$C$7-1)/$C$7) -> 0.0083319985 | W23: =C$13*$F23 -> 0.0095201194 | X23: =D$13*$F23 -> 0.019040239 | Y23: =E$13*$F23 -> 0 | Z23: =F$13*$F23 -> 0
B24: S09 | C24: Accommodation & Food Services | D24: =Oman_Intensity!F14 -> 730.03078 | E24: =Oman_Intensity!G14 -> 0.35 | F24: =Oman_Intensity!H14 -> 1 | G24: =IF($D24<=0,0,C$10*$D24*C$11*(1-$E24)/(1000000*C$12)) -> 0.26905285 | H24: =IF($D24<=0,0,D$10*$D24*D$11*(1-$E24)/(1000000*D$12)) -> 0.10569933 | I24: =IF($D24<=0,0,E$10*$D24*E$11*(1-$E24)/(1000000*E$12)) -> 0.0051248161 | J24: =IF($D24<=0,0,F$10*$D24*F$11*(1-$E24)/(1000000*F$12)) -> 0.02242107 | K24: =Physical_Exposure!D33 -> 0.0056719972 | L24: =Physical_Exposure!E33 -> 0.0062809294 | M24: =Physical_Exposure!F33 -> 0.009393502 | N24: =Physical_Exposure!G33 -> 0.0078581776 | O24: =MIN(G24+K24,k_MultiAnchor!$C$60) -> 0.27472484 | P24: =MIN(H24+L24,k_MultiAnchor!$C$60) -> 0.11198026 | Q24: =MIN(I24+M24,k_MultiAnchor!$C$60) -> 0.014518318 | R24: =MIN(J24+N24,k_MultiAnchor!$C$60) -> 0.030279248 | S24: =$C$5*IF(ABS($C$7)<0.000000000001,LN(1+O24),((1+O24)^$C$7-1)/$C$7) -> 0.06384045 | T24: =$C$5*IF(ABS($C$7)<0.000000000001,LN(1+P24),((1+P24)^$C$7-1)/$C$7) -> 0.027916499 | U24: =$C$5*IF(ABS($C$7)<0.000000000001,LN(1+Q24),((1+Q24)^$C$7-1)/$C$7) -> 0.003791006 | V24: =$C$5*IF(ABS($C$7)<0.000000000001,LN(1+R24),((1+R24)^$C$7-1)/$C$7) -> 0.0078455496 | W24: =C$13*$F24 -> 0.0095201194 | X24: =D$13*$F24 -> 0.019040239 | Y24: =E$13*$F24 -> 0 | Z24: =F$13*$F24 -> 0
B25: S10 | C25: Financial, Professional, Public & Other Services | D25: =Oman_Intensity!F15 -> 161.89863 | E25: =Oman_Intensity!G15 -> 0.6 | F25: =Oman_Intensity!H15 -> 1 | G25: =IF($D25<=0,0,C$10*$D25*C$11*(1-$E25)/(1000000*C$12)) -> 0.036718609 | H25: =IF($D25<=0,0,D$10*$D25*D$11*(1-$E25)/(1000000*D$12)) -> 0.014425168 | I25: =IF($D25<=0,0,E$10*$D25*E$11*(1-$E25)/(1000000*E$12)) -> 0.00069940208 | J25: =IF($D25<=0,0,F$10*$D25*F$11*(1-$E25)/(1000000*F$12)) -> 0.0030598841 | K25: =Physical_Exposure!D34 -> 0.001634379 | L25: =Physical_Exposure!E34 -> 0.0018214048 | M25: =Physical_Exposure!F34 -> 0.0027917362 | N25: =Physical_Exposure!G34 -> 0.0023104411 | O25: =MIN(G25+K25,k_MultiAnchor!$C$60) -> 0.038352988 | P25: =MIN(H25+L25,k_MultiAnchor!$C$60) -> 0.016246573 | Q25: =MIN(I25+M25,k_MultiAnchor!$C$60) -> 0.0034911382 | R25: =MIN(J25+N25,k_MultiAnchor!$C$60) -> 0.0053703252 | S25: =$C$5*IF(ABS($C$7)<0.000000000001,LN(1+O25),((1+O25)^$C$7-1)/$C$7) -> 0.0098985808 | T25: =$C$5*IF(ABS($C$7)<0.000000000001,LN(1+P25),((1+P25)^$C$7-1)/$C$7) -> 0.0042386678 | U25: =$C$5*IF(ABS($C$7)<0.000000000001,LN(1+Q25),((1+Q25)^$C$7-1)/$C$7) -> 0.00091660436 | V25: =$C$5*IF(ABS($C$7)<0.000000000001,LN(1+R25),((1+R25)^$C$7-1)/$C$7) -> 0.0014086688 | W25: =C$13*$F25 -> 0.0095201194 | X25: =D$13*$F25 -> 0.019040239 | Y25: =E$13*$F25 -> 0 | Z25: =F$13*$F25 -> 0
B28: Sector ID | C28: Sector | D28: Grade | E28: Key | F28: Baseline PD | G28: Stressed PD NZ | H28: Stressed PD DT | I28: Stressed PD CP | J28: Stressed PD FW | K28: PD multiple NZ | L28: PD multiple DT | M28: PD multiple CP | N28: PD multiple FW
B29: =$B$16 -> S01 | C29: =$C$16 -> Agriculture, Forestry & Fishing | D29: MR1 | E29: =B29&"|"&D29 -> S01|MR1 | F29: =INDEX(RatingGrades!$C$6:$C$12,MATCH(D29,RatingGrades!$B$6:$B$12,0)) -> 0.001 | G29: =NORMSDIST(NORMSINV($F29)+S$16+W$16) -> 0.0013175537 | H29: =NORMSDIST(NORMSINV($F29)+T$16+X$16) -> 0.0011940951 | I29: =NORMSDIST(NORMSINV($F29)+U$16+Y$16) -> 0.0010295097 | J29: =NORMSDIST(NORMSINV($F29)+V$16+Z$16) -> 0.0010426847 | K29: =G29/$F29 -> 1.3175537 | L29: =H29/$F29 -> 1.1940951 | M29: =I29/$F29 -> 1.0295097 | N29: =J29/$F29 -> 1.0426847
B30: =$B$16 -> S01 | C30: =$C$16 -> Agriculture, Forestry & Fishing | D30: MR2 | E30: =B30&"|"&D30 -> S01|MR2 | F30: =INDEX(RatingGrades!$C$6:$C$12,MATCH(D30,RatingGrades!$B$6:$B$12,0)) -> 0.0025 | G30: =NORMSDIST(NORMSINV($F30)+S$16+W$16) -> 0.0032230608 | H30: =NORMSDIST(NORMSINV($F30)+T$16+X$16) -> 0.0029439392 | I30: =NORMSDIST(NORMSINV($F30)+U$16+Y$16) -> 0.0025679342 | J30: =NORMSDIST(NORMSINV($F30)+V$16+Z$16) -> 0.0025982109 | K30: =G30/$F30 -> 1.2892243 | L30: =H30/$F30 -> 1.1775757 | M30: =I30/$F30 -> 1.0271737 | N30: =J30/$F30 -> 1.0392843
B31: =$B$16 -> S01 | C31: =$C$16 -> Agriculture, Forestry & Fishing | D31: MR3 | E31: =B31&"|"&D31 -> S01|MR3 | F31: =INDEX(RatingGrades!$C$6:$C$12,MATCH(D31,RatingGrades!$B$6:$B$12,0)) -> 0.005 | G31: =NORMSDIST(NORMSINV($F31)+S$16+W$16) -> 0.0063338651 | H31: =NORMSDIST(NORMSINV($F31)+T$16+X$16) -> 0.0058219493 | I31: =NORMSDIST(NORMSINV($F31)+U$16+Y$16) -> 0.0051264449 | J31: =NORMSDIST(NORMSINV($F31)+V$16+Z$16) -> 0.0051827177 | K31: =G31/$F31 -> 1.266773 | L31: =H31/$F31 -> 1.1643899 | M31: =I31/$F31 -> 1.025289 | N31: =J31/$F31 -> 1.0365435
B32: =$B$16 -> S01 | C32: =$C$16 -> Agriculture, Forestry & Fishing | D32: MR4 | E32: =B32&"|"&D32 -> S01|MR4 | F32: =INDEX(RatingGrades!$C$6:$C$12,MATCH(D32,RatingGrades!$B$6:$B$12,0)) -> 0.01 | G32: =NORMSDIST(NORMSINV($F32)+S$16+W$16) -> 0.01243246 | H32: =NORMSDIST(NORMSINV($F32)+T$16+X$16) -> 0.011504803 | I32: =NORMSDIST(NORMSINV($F32)+U$16+Y$16) -> 0.010232811 | J32: =NORMSDIST(NORMSINV($F32)+V$16+Z$16) -> 0.01033626 | K32: =G32/$F32 -> 1.243246 | L32: =H32/$F32 -> 1.1504803 | M32: =I32/$F32 -> 1.0232811 | N32: =J32/$F32 -> 1.033626
B33: =$B$16 -> S01 | C33: =$C$16 -> Agriculture, Forestry & Fishing | D33: MR5 | E33: =B33&"|"&D33 -> S01|MR5 | F33: =INDEX(RatingGrades!$C$6:$C$12,MATCH(D33,RatingGrades!$B$6:$B$12,0)) -> 0.02 | G33: =NORMSDIST(NORMSINV($F33)+S$16+W$16) -> 0.024367892 | H33: =NORMSDIST(NORMSINV($F33)+T$16+X$16) -> 0.022713651 | I33: =NORMSDIST(NORMSINV($F33)+U$16+Y$16) -> 0.02042244 | J33: =NORMSDIST(NORMSINV($F33)+V$16+Z$16) -> 0.020609834 | K33: =G33/$F33 -> 1.2183946 | L33: =H33/$F33 -> 1.1356826 | M33: =I33/$F33 -> 1.021122 | N33: =J33/$F33 -> 1.0304917
B34: =$B$16 -> S01 | C34: =$C$16 -> Agriculture, Forestry & Fishing | D34: MR6 | E34: =B34&"|"&D34 -> S01|MR6 | F34: =INDEX(RatingGrades!$C$6:$C$12,MATCH(D34,RatingGrades!$B$6:$B$12,0)) -> 0.045 | G34: =NORMSDIST(NORMSINV($F34)+S$16+W$16) -> 0.05342173 | H34: =NORMSDIST(NORMSINV($F34)+T$16+X$16) -> 0.050261341 | I34: =NORMSDIST(NORMSINV($F34)+U$16+Y$16) -> 0.045825715 | J34: =NORMSDIST(NORMSINV($F34)+V$16+Z$16) -> 0.046191187 | K34: =G34/$F34 -> 1.1871496 | L34: =H34/$F34 -> 1.1169187 | M34: =I34/$F34 -> 1.0183492 | N34: =J34/$F34 -> 1.0264708
B35: =$B$16 -> S01 | C35: =$C$16 -> Agriculture, Forestry & Fishing | D35: MR7 | E35: =B35&"|"&D35 -> S01|MR7 | F35: =INDEX(RatingGrades!$C$6:$C$12,MATCH(D35,RatingGrades!$B$6:$B$12,0)) -> 0.1 | G35: =NORMSDIST(NORMSINV($F35)+S$16+W$16) -> 0.11532259 | H35: =NORMSDIST(NORMSINV($F35)+T$16+X$16) -> 0.10963364 | I35: =NORMSDIST(NORMSINV($F35)+U$16+Y$16) -> 0.10152608 | J35: =NORMSDIST(NORMSINV($F35)+V$16+Z$16) -> 0.1021998 | K35: =G35/$F35 -> 1.1532259 | L35: =H35/$F35 -> 1.0963364 | M35: =I35/$F35 -> 1.0152608 | N35: =J35/$F35 -> 1.021998
B36: =$B$17 -> S02 | C36: =$C$17 -> Oil & Gas Extraction | D36: MR1 | E36: =B36&"|"&D36 -> S02|MR1 | F36: =INDEX(RatingGrades!$C$6:$C$12,MATCH(D36,RatingGrades!$B$6:$B$12,0)) -> 0.001 | G36: =NORMSDIST(NORMSINV($F36)+S$17+W$17) -> 0.0015897701 | H36: =NORMSDIST(NORMSINV($F36)+T$17+X$17) -> 0.0013027372 | I36: =NORMSDIST(NORMSINV($F36)+U$17+Y$17) -> 0.001020723 | J36: =NORMSDIST(NORMSINV($F36)+V$17+Z$17) -> 0.001055015 | K36: =G36/$F36 -> 1.5897701 | L36: =H36/$F36 -> 1.3027372 | M36: =I36/$F36 -> 1.020723 | N36: =J36/$F36 -> 1.055015
B37: =$B$17 -> S02 | C37: =$C$17 -> Oil & Gas Extraction | D37: MR2 | E37: =B37&"|"&D37 -> S02|MR2 | F37: =INDEX(RatingGrades!$C$6:$C$12,MATCH(D37,RatingGrades!$B$6:$B$12,0)) -> 0.0025 | G37: =NORMSDIST(NORMSINV($F37)+S$17+W$17) -> 0.0038308392 | H37: =NORMSDIST(NORMSINV($F37)+T$17+X$17) -> 0.0031896856 | I37: =NORMSDIST(NORMSINV($F37)+U$17+Y$17) -> 0.0025477236 | J37: =NORMSDIST(NORMSINV($F37)+V$17+Z$17) -> 0.0026265174 | K37: =G37/$F37 -> 1.5323357 | L37: =H37/$F37 -> 1.2758743 | M37: =I37/$F37 -> 1.0190894 | N37: =J37/$F37 -> 1.0506069
B38: =$B$17 -> S02 | C38: =$C$17 -> Oil & Gas Extraction | D38: MR3 | E38: =B38&"|"&D38 -> S02|MR3 | F38: =INDEX(RatingGrades!$C$6:$C$12,MATCH(D38,RatingGrades!$B$6:$B$12,0)) -> 0.005 | G38: =NORMSDIST(NORMSINV($F38)+S$17+W$17) -> 0.0074372165 | H38: =NORMSDIST(NORMSINV($F38)+T$17+X$17) -> 0.0062728378 | I38: =NORMSDIST(NORMSINV($F38)+U$17+Y$17) -> 0.0050888537 | J38: =NORMSDIST(NORMSINV($F38)+V$17+Z$17) -> 0.0052352843 | K38: =G38/$F38 -> 1.4874433 | L38: =H38/$F38 -> 1.2545676 | M38: =I38/$F38 -> 1.0177707 | N38: =J38/$F38 -> 1.0470569
B39: =$B$17 -> S02 | C39: =$C$17 -> Oil & Gas Extraction | D39: MR4 | E39: =B39&"|"&D39 -> S02|MR4 | F39: =INDEX(RatingGrades!$C$6:$C$12,MATCH(D39,RatingGrades!$B$6:$B$12,0)) -> 0.01 | G39: =NORMSDIST(NORMSINV($F39)+S$17+W$17) -> 0.014409978 | H39: =NORMSDIST(NORMSINV($F39)+T$17+X$17) -> 0.012322229 | I39: =NORMSDIST(NORMSINV($F39)+U$17+Y$17) -> 0.01016365 | J39: =NORMSDIST(NORMSINV($F39)+V$17+Z$17) -> 0.010432808 | K39: =G39/$F39 -> 1.4409978 | L39: =H39/$F39 -> 1.2322229 | M39: =I39/$F39 -> 1.016365 | N39: =J39/$F39 -> 1.0432808
B40: =$B$17 -> S02 | C40: =$C$17 -> Oil & Gas Extraction | D40: MR5 | E40: =B40&"|"&D40 -> S02|MR5 | F40: =INDEX(RatingGrades!$C$6:$C$12,MATCH(D40,RatingGrades!$B$6:$B$12,0)) -> 0.02 | G40: =NORMSDIST(NORMSINV($F40)+S$17+W$17) -> 0.02785217 | H40: =NORMSDIST(NORMSINV($F40)+T$17+X$17) -> 0.024172019 | I40: =NORMSDIST(NORMSINV($F40)+U$17+Y$17) -> 0.02029705 | J40: =NORMSDIST(NORMSINV($F40)+V$17+Z$17) -> 0.020784553 | K40: =G40/$F40 -> 1.3926085 | L40: =H40/$F40 -> 1.2086009 | M40: =I40/$F40 -> 1.0148525 | N40: =J40/$F40 -> 1.0392276
B41: =$B$17 -> S02 | C41: =$C$17 -> Oil & Gas Extraction | D41: MR6 | E41: =B41&"|"&D41 -> S02|MR6 | F41: =INDEX(RatingGrades!$C$6:$C$12,MATCH(D41,RatingGrades!$B$6:$B$12,0)) -> 0.045 | G41: =NORMSDIST(NORMSINV($F41)+S$17+W$17) -> 0.059974182 | H41: =NORMSDIST(NORMSINV($F41)+T$17+X$17) -> 0.053049263 | I41: =NORMSDIST(NORMSINV($F41)+U$17+Y$17) -> 0.045580891 | J41: =NORMSDIST(NORMSINV($F41)+V$17+Z$17) -> 0.046531495 | K41: =G41/$F41 -> 1.3327596 | L41: =H41/$F41 -> 1.1788725 | M41: =I41/$F41 -> 1.0129087 | N41: =J41/$F41 -> 1.0340332
B42: =$B$17 -> S02 | C42: =$C$17 -> Oil & Gas Extraction | D42: MR7 | E42: =B42&"|"&D42 -> S02|MR7 | F42: =INDEX(RatingGrades!$C$6:$C$12,MATCH(D42,RatingGrades!$B$6:$B$12,0)) -> 0.1 | G42: =NORMSDIST(NORMSINV($F42)+S$17+W$17) -> 0.12690496 | H42: =NORMSDIST(NORMSINV($F42)+T$17+X$17) -> 0.11465574 | I42: =NORMSDIST(NORMSINV($F42)+U$17+Y$17) -> 0.10107416 | J42: =NORMSDIST(NORMSINV($F42)+V$17+Z$17) -> 0.1028262 | K42: =G42/$F42 -> 1.2690496 | L42: =H42/$F42 -> 1.1465574 | M42: =I42/$F42 -> 1.0107416 | N42: =J42/$F42 -> 1.028262
B43: =$B$18 -> S03 | C43: =$C$18 -> Mining & Quarrying (non-oil) | D43: MR1 | E43: =B43&"|"&D43 -> S03|MR1 | F43: =INDEX(RatingGrades!$C$6:$C$12,MATCH(D43,RatingGrades!$B$6:$B$12,0)) -> 0.001 | G43: =NORMSDIST(NORMSINV($F43)+S$18+W$18) -> 0.0015034886 | H43: =NORMSDIST(NORMSINV($F43)+T$18+X$18) -> 0.0012688953 | I43: =NORMSDIST(NORMSINV($F43)+U$18+Y$18) -> 0.0010262364 | J43: =NORMSDIST(NORMSINV($F43)+V$18+Z$18) -> 0.0010529296 | K43: =G43/$F43 -> 1.5034886 | L43: =H43/$F43 -> 1.2688953 | M43: =I43/$F43 -> 1.0262364 | N43: =J43/$F43 -> 1.0529296
B44: =$B$18 -> S03 | C44: =$C$18 -> Mining & Quarrying (non-oil) | D44: MR2 | E44: =B44&"|"&D44 -> S03|MR2 | F44: =INDEX(RatingGrades!$C$6:$C$12,MATCH(D44,RatingGrades!$B$6:$B$12,0)) -> 0.0025 | G44: =NORMSDIST(NORMSINV($F44)+S$18+W$18) -> 0.0036392573 | H44: =NORMSDIST(NORMSINV($F44)+T$18+X$18) -> 0.0031133312 | I44: =NORMSDIST(NORMSINV($F44)+U$18+Y$18) -> 0.0025604068 | J44: =NORMSDIST(NORMSINV($F44)+V$18+Z$18) -> 0.0026217319 | K44: =G44/$F44 -> 1.4557029 | L44: =H44/$F44 -> 1.2453325 | M44: =I44/$F44 -> 1.0241627 | N44: =J44/$F44 -> 1.0486928
...

Sheet Sector_Master
B1: Sector master: 10-sector taxonomy, complete ISIC coverage
B2: Every ISIC Rev.4 section sits in exactly one sector. Every sector's GVA comes from the source, not from a judgemental split of a parent. There are no zero-GVA rows, which is what caused the real-estate problem in v3: ISIC L, E, N and R are not itemised in Oman's SNA submission but are absorbed inside the lines that are, so they are folded into their parent sector rather than given empty rows of their own.
B4: Denominator basis (GVA or TURNOVER) | C4: GVA | E4: See ReadMe and the note below the table for why GVA is the default.
B5: OMR / US$ peg | C5: 2.6008
B7: ID | C7: Sector | D7: ISIC Rev.4 sections | E7: GVA 2023 (OMR m) | F7: GVA 2023 (US$ m) | G7: Turnover / GVA | H7: Denominator (US$ m) | I7: Pass-through | J7: macro_beta | K7: Pass-through rationale (trade-exposure basis)
B8: S01 | C8: Agriculture, Forestry & Fishing | D8: A | E8: 996.81484 | F8: =E8*$C$5 -> 2592.516 | G8: 1 | H8: =IF($C$4="TURNOVER",F8*G8,F8) -> 2592.516 | I8: 0.25 | J8: 1 | K8: Commodity price-takers, partly supported by domestic subsidy. Low pass-through.
B9: S02 | C9: Oil & Gas Extraction | D9: B (petroleum part) | E9: 14750.294 | F9: =E9*$C$5 -> 38362.564 | G9: 1 | H9: =IF($C$4="TURNOVER",F9*G9,F9) -> 38362.564 | I9: 0.05 | J9: 1 | K9: World-priced crude and LNG. A domestic carbon cost cannot be passed to an international buyer. Near-zero pass-through.
B10: S03 | C10: Mining & Quarrying (non-oil) | D10: B (remainder) | E10: 205.8 | F10: =E10*$C$5 -> 535.24464 | G10: 1 | H10: =IF($C$4="TURNOVER",F10*G10,F10) -> 535.24464 | I10: 0.3 | J10: 1 | K10: Limestone, gypsum, chromite, copper. Part exported at world prices, part sold into the domestic construction chain.
B11: S04 | C11: Manufacturing | D11: C | E11: 3819.7517 | F11: =E11*$C$5 -> 9934.4102 | G11: 1 | H11: =IF($C$4="TURNOVER",F11*G11,F11) -> 9934.4102 | I11: 0.3 | J11: 1 | K11: Dominated in Oman by refining, petrochemicals and metals, all internationally traded against unabated Gulf and Asian competitors. Weighted below the 45% base rate for that reason.
B12: S05 | C12: Electricity, Gas, Water & Waste | D12: D, E | E12: 970.07565 | F12: =E12*$C$5 -> 2522.9728 | G12: 1 | H12: =IF($C$4="TURNOVER",F12*G12,F12) -> 2522.9728 | I12: 0.8 | J12: 1 | K12: Regulated tariffs with cost recovery through the regulator and state subsidy. Cost migrates to the sovereign rather than the utility. Corollary: residual credit risk becomes sovereign-linked, which this model does not capture.
B13: S06 | C13: Construction | D13: F | E13: 2766.3441 | F13: =E13*$C$5 -> 7194.7077 | G13: 1 | H13: =IF($C$4="TURNOVER",F13*G13,F13) -> 7194.7077 | I13: 0.5 | J13: 1 | K13: Domestic, contract-based. Cost-escalation clauses on long contracts, fixed price on many others.
B14: S07 | C14: Wholesale & Retail Trade | D14: G | E14: 3165.6894 | F14: =E14*$C$5 -> 8233.325 | G14: 1 | H14: =IF($C$4="TURNOVER",F14*G14,F14) -> 8233.325 | I14: 0.7 | J14: 1 | K14: Passes input cost to the final consumer over the medium term. Thin margins but high pass-through.
B15: S08 | C15: Transport & Storage | D15: H | E15: 1680.826 | F15: =E15*$C$5 -> 4371.4922 | G15: 1 | H15: =IF($C$4="TURNOVER",F15*G15,F15) -> 4371.4922 | I15: 0.6 | J15: 1 | K15: Fuel surcharges are standard contractual practice in freight and warehousing; partly offset by international competition in shipping and aviation.
B16: S09 | C16: Accommodation & Food Services | D16: I | E16: 585.41162 | F16: =E16*$C$5 -> 1522.5385 | G16: 1 | H16: =IF($C$4="TURNOVER",F16*G16,F16) -> 1522.5385 | I16: 0.35 | J16: 1 | K16: Price-elastic international demand competing with regional destinations. Below-average pass-through.
B17: S10 | C17: Financial, Professional, Public & Other Services | D17: J, K, L, M, N, O, P, Q, R, S, T | E17: 13022.9 | F17: =E17*$C$5 -> 33869.959 | G17: 1 | H17: =IF($C$4="TURNOVER",F17*G17,F17) -> 33869.959 | I17: 0.6 | J17: 1 | K17: Domestic and largely non-traded. Includes real estate (ISIC L), which Oman's SNA submission does not itemise separately.
C18: Total | E18: =SUM(E8:E17) -> 41963.907
C19: UN SNA Table 2.4, total value added at basic prices, 2023 | E19: 41963.907
C20: Reconciliation | E20: =IF(ABS(E18-E19)<0.01,"PASS","FAIL") -> PASS
B22: WHY GVA AND NOT TURNOVER. Turnover is the better denominator on comparability grounds, because the EU literature (ECB OP 281, EU ETS carbon-leakage work) reports emission intensity per unit of revenue. It is not used here for one reason: Oman does not publish output or turnover by ISIC activity. NCSI publishes value added by activity; output at basic prices would require the supply-use table, which is not public. GVA is therefore the only denominator that exists for every sector in this list. Two consequences follow. First, the EU anchor must be converted onto a GVA basis, which is done explicitly on EU_k_Calibration rather than left as an implicit unit mismatch. Second, if the bank can obtain turnover by sector, switch cell C4 to TURNOVER, populate column G, and the model runs on a revenue basis end to end.
B26: There is also an argument that GVA is the more meaningful denominator for default risk, since GVA is approximately EBITDA plus labour compensation, i.e. the funds actually available to absorb a cost shock, whereas revenue is not. The decisive point, though, is data availability, and the two bases must never be mixed as they were in v2.
B29: TIMING: GVA is 2023 current prices. Emissions are 2024 EDGAR. See Verification item 18 for the 2024 replacement values.

Sheet Emissions_Allocation
B1: Emissions allocation: EDGAR IPCC categories onto the lending taxonomy
B2: EDGAR reports emissions by IPCC SOURCE category; a bank lends to ISIC ACTIVITIES. Each EDGAR row is split across lending sectors plus a Households and own-account column that is excluded from every corporate intensity.
B5: Code | C5: EDGAR category | D5: MtCO2e | E5: Definition | F5: S01 | G5: S02 | H5: S03 | I5: S04 | J5: S05 | K5: S06 | L5: S07 | M5: S08 | N5: S09 | O5: S10 | P5: HH | Q5: Row sum | R5: Check
B6: E1 | C6: Fuel Exploitation | D6: 42.24 | E6: Upstream oil and gas: fugitive methane, venting, flaring, own energy use. IPCC 1B. | F6: 0 | G6: 1 | H6: 0 | I6: 0 | J6: 0 | K6: 0 | L6: 0 | M6: 0 | N6: 0 | O6: 0 | P6: 0 | Q6: =SUM(F6:P6) -> 1 | R6: =IF(ABS(Q6-1)<0.000001,"OK","FAIL") -> OK
B7: E2 | C7: Power Industry | D7: 17.15 | E7: Public electricity and heat generation. IPCC 1A1a. | F7: 0 | G7: 0 | H7: 0 | I7: 0 | J7: 1 | K7: 0 | L7: 0 | M7: 0 | N7: 0 | O7: 0 | P7: 0 | Q7: =SUM(F7:P7) -> 1 | R7: =IF(ABS(Q7-1)<0.000001,"OK","FAIL") -> OK
B8: E3 | C8: Industrial Combustion | D8: 14.29 | E8: Fuel combustion in manufacturing industries AND construction. IPCC 1A2. | F8: 0 | G8: 0 | H8: 0.05 | I8: 0.85 | J8: 0 | K8: 0.1 | L8: 0 | M8: 0 | N8: 0 | O8: 0 | P8: 0 | Q8: =SUM(F8:P8) -> 1 | R8: =IF(ABS(Q8-1)<0.000001,"OK","FAIL") -> OK
B9: E4 | C9: Transport | D9: 13.01 | E9: Road, domestic aviation, domestic navigation, rail. INCLUDES private household vehicles. IPCC 1A3. | F9: 0 | G9: 0 | H9: 0 | I9: 0 | J9: 0 | K9: 0 | L9: 0.1 | M9: 0.4 | N9: 0 | O9: 0 | P9: 0.5 | Q9: =SUM(F9:P9) -> 1 | R9: =IF(ABS(Q9-1)<0.000001,"OK","FAIL") -> OK
B10: E5 | C10: Agriculture | D10: 1.86 | E10: Enteric fermentation, manure, soils, agricultural fuel use. IPCC 3. | F10: 1 | G10: 0 | H10: 0 | I10: 0 | J10: 0 | K10: 0 | L10: 0 | M10: 0 | N10: 0 | O10: 0 | P10: 0 | Q10: =SUM(F10:P10) -> 1 | R10: =IF(ABS(Q10-1)<0.000001,"OK","FAIL") -> OK
B11: E6 | C11: Buildings | D11: 22.23 | E11: Residential, commercial and institutional fuel combustion, i.e. building OCCUPANCY energy. IPCC 1A4. NOT the construction industry. | F11: 0 | G11: 0 | H11: 0 | I11: 0 | J11: 0 | K11: 0 | L11: 0.1 | M11: 0 | N11: 0.05 | O11: 0.15 | P11: 0.7 | Q11: =SUM(F11:P11) -> 1 | R11: =IF(ABS(Q11-1)<0.000001,"OK","FAIL") -> OK
B12: E7 | C12: Residual (industrial processes, waste, other) | D12: =$D$14-SUM(D6:D11) -> 21.49 | E12: PLUG: national total less the six categories above. | F12: 0 | G12: 0.15 | H12: 0 | I12: 0.4 | J12: 0.25 | K12: 0 | L12: 0 | M12: 0 | N12: 0 | O12: 0.1 | P12: 0.1 | Q12: =SUM(F12:P12) -> 1 | R12: =IF(ABS(Q12-1)<0.000001,"OK","FAIL") -> OK
C13: Sum of categories | D13: =SUM(D6:D12) -> 132.27
C14: National total GHG (MtCO2e) | D14: 132.27
C15: Reconciliation | D15: =IF(ABS(D13-D14)<0.001,"PASS","FAIL") -> PASS
C16: Allocated emissions by lending sector (MtCO2e)
C17: Allocated MtCO2e | F17: =SUMPRODUCT($D$6:$D$12,F6:F12) -> 1.86 | G17: =SUMPRODUCT($D$6:$D$12,G6:G12) -> 45.4635 | H17: =SUMPRODUCT($D$6:$D$12,H6:H12) -> 0.7145 | I17: =SUMPRODUCT($D$6:$D$12,I6:I12) -> 20.7425 | J17: =SUMPRODUCT($D$6:$D$12,J6:J12) -> 22.5225 | K17: =SUMPRODUCT($D$6:$D$12,K6:K12) -> 1.429 | L17: =SUMPRODUCT($D$6:$D$12,L6:L12) -> 3.524 | M17: =SUMPRODUCT($D$6:$D$12,M6:M12) -> 5.204 | ... P17: =SUMPRODUCT($D$6:$D$12,P6:P12) -> 24.215 | Q17: =SUM(F17:P17) -> 132.27 | R17: =IF(ABS(Q17-D14)<0.001,"OK","FAIL") -> OK
C18: Sector ID | F18: S01 | G18: S02 | H18: S03 | I18: S04 | J18: S05 | K18: S06 | L18: S07 | M18: S08 | N18: S09 | O18: S10 | P18: HH
C20: Plausibility checks
C21: Population (millions) | D21: 5.3
C22: National emissions per head (tCO2e) | D22: =D14/D21 -> 24.956604 | E22: High, but consistent with Oman being among the highest per-capita emitters globally. Not a fail.
C23: EDGAR Buildings per head (tCO2e) | D23: =D11/D21 -> 4.1943396 | E23: =IF(D23>3,"FLAG - implausibly high, re-download EDGAR","OK") -> FLAG - implausibly high, re-download EDGAR
E24: This is DIRECT fuel combustion in buildings only; air conditioning electricity is already counted under Power Industry. Above roughly 3 tCO2e per head the figure is not credible for a hot climate. Seventy per cent is allocated to households so it does not distort corporate intensities, but the underlying figure should be re-checked.
C26: Corporate share of national emissions | D26: =(Q17-P17)/Q17 -> 0.8169275
C27: The remainder is households and own-account use: private vehicles and residential building energy. In v2 these were charged to Transport & Logistics and to Construction respectively.
C29: The three shaded allocation rows that carry judgement are E3 (industrial combustion across manufacturing, mining and construction), E4 (transport between freight operators and households) and E6 (buildings between households and commercial occupiers), plus the E7 residual. Replace with an EDGAR sub-sector download or an ISIC-basis emissions account from Eora, EXIOBASE or GTAP, reconciled to the EDGAR national total.

Sheet Oman_Intensity
B1: Emissions intensity by sector
B2: Basis: tCO2e all-gas Scope 1 per US$ million of the denominator selected on Sector_Master (GVA by default). The same basis is used in EU_k_Calibration.
B5: ID | C5: Sector | D5: Emissions (MtCO2e) | E5: Denominator (US$ m) | F5: Intensity (tCO2e / US$m) | G5: Pass-through | H5: macro_beta | I5: Note
B6: S01 | C6: Agriculture, Forestry & Fishing | D6: =INDEX(Emissions_Allocation!$F$17:$O$17,MATCH($B6,Emissions_Allocation!$F$18:$O$18,0)) -> 1.86 | E6: =Sector_Master!H8 -> 2592.516 | F6: =IF(E6<=0,0,D6*1000000/E6) -> 717.44975 | G6: =Sector_Master!I8 -> 0.25 | H6: =Sector_Master!J8 -> 1
B7: S02 | C7: Oil & Gas Extraction | D7: =INDEX(Emissions_Allocation!$F$17:$O$17,MATCH($B7,Emissions_Allocation!$F$18:$O$18,0)) -> 45.4635 | E7: =Sector_Master!H9 -> 38362.564 | F7: =IF(E7<=0,0,D7*1000000/E7) -> 1185.1007 | G7: =Sector_Master!I9 -> 0.05 | H7: =Sector_Master!J9 -> 1
B8: S03 | C8: Mining & Quarrying (non-oil) | D8: =INDEX(Emissions_Allocation!$F$17:$O$17,MATCH($B8,Emissions_Allocation!$F$18:$O$18,0)) -> 0.7145 | E8: =Sector_Master!H10 -> 535.24464 | F8: =IF(E8<=0,0,D8*1000000/E8) -> 1334.9036 | G8: =Sector_Master!I10 -> 0.3 | H8: =Sector_Master!J10 -> 1
B9: S04 | C9: Manufacturing | D9: =INDEX(Emissions_Allocation!$F$17:$O$17,MATCH($B9,Emissions_Allocation!$F$18:$O$18,0)) -> 20.7425 | E9: =Sector_Master!H11 -> 9934.4102 | F9: =IF(E9<=0,0,D9*1000000/E9) -> 2087.9448 | G9: =Sector_Master!I11 -> 0.3 | H9: =Sector_Master!J11 -> 1
B10: S05 | C10: Electricity, Gas, Water & Waste | D10: =INDEX(Emissions_Allocation!$F$17:$O$17,MATCH($B10,Emissions_Allocation!$F$18:$O$18,0)) -> 22.5225 | E10: =Sector_Master!H12 -> 2522.9728 | F10: =IF(E10<=0,0,D10*1000000/E10) -> 8926.9692 | G10: =Sector_Master!I12 -> 0.8 | H10: =Sector_Master!J12 -> 1
B11: S06 | C11: Construction | D11: =INDEX(Emissions_Allocation!$F$17:$O$17,MATCH($B11,Emissions_Allocation!$F$18:$O$18,0)) -> 1.429 | E11: =Sector_Master!H13 -> 7194.7077 | F11: =IF(E11<=0,0,D11*1000000/E11) -> 198.61822 | G11: =Sector_Master!I13 -> 0.5 | H11: =Sector_Master!J13 -> 1
B12: S07 | C12: Wholesale & Retail Trade | D12: =INDEX(Emissions_Allocation!$F$17:$O$17,MATCH($B12,Emissions_Allocation!$F$18:$O$18,0)) -> 3.524 | E12: =Sector_Master!H14 -> 8233.325 | F12: =IF(E12<=0,0,D12*1000000/E12) -> 428.01663 | G12: =Sector_Master!I14 -> 0.7 | H12: =Sector_Master!J14 -> 1
B13: S08 | C13: Transport & Storage | D13: =INDEX(Emissions_Allocation!$F$17:$O$17,MATCH($B13,Emissions_Allocation!$F$18:$O$18,0)) -> 5.204 | E13: =Sector_Master!H15 -> 4371.4922 | F13: =IF(E13<=0,0,D13*1000000/E13) -> 1190.4402 | G13: =Sector_Master!I15 -> 0.6 | H13: =Sector_Master!J15 -> 1
B14: S09 | C14: Accommodation & Food Services | D14: =INDEX(Emissions_Allocation!$F$17:$O$17,MATCH($B14,Emissions_Allocation!$F$18:$O$18,0)) -> 1.1115 | E14: =Sector_Master!H16 -> 1522.5385 | F14: =IF(E14<=0,0,D14*1000000/E14) -> 730.03078 | G14: =Sector_Master!I16 -> 0.35 | H14: =Sector_Master!J16 -> 1
B15: S10 | C15: Financial, Professional, Public & Other Services | D15: =INDEX(Emissions_Allocation!$F$17:$O$17,MATCH($B15,Emissions_Allocation!$F$18:$O$18,0)) -> 5.4835 | E15: =Sector_Master!H17 -> 33869.959 | F15: =IF(E15<=0,0,D15*1000000/E15) -> 161.89863 | G15: =Sector_Master!I17 -> 0.6 | H15: =Sector_Master!J17 -> 1
C16: Total | D16: =SUM(D6:D15) -> 108.055 | E16: =SUM(E6:E15) -> 109139.73
C17: Implied economy-wide intensity (corporate only) | F17: =D16*1000000/E16 -> 990.06109
B19: Sectors with zero intensity are impossible in this taxonomy because every sector has a positive denominator and a positive emissions allocation. That was the v3 defect, caused by creating rows for ISIC sections that Oman does not itemise.

Sheet NGFS_CarbonPrice
B1: NGFS Phase V shadow carbon price
B5: Scenario | C5: 2030 | D5: 2035 | E5: 2040 | F5: 2050
B6: Net Zero 2050 | C6: 200 | D6: 294 | E6: 420 | F6: 630
B7: Delayed Transition | C7: 5 | D7: 100 | E7: 165 | F7: 315
B8: Current Policies | C8: 5 | D8: 6 | E8: 8 | F8: 10
B9: Fragmented World | C9: 5 | D9: 20 | E9: 35 | F9: 55
B11: Unit: US$2010 per tCO2. VERIFIED against NGFS Phase V, Main results, Carbon prices: both published charts are labelled US$2010/tCO2.
B12: VERIFIED: the report states that a shadow price of around $300/tCO2 is needed by 2035 to incentivise net zero by 2050, an increase from $98/tCO2 in 2025 to $294/tCO2 within ten years. The Net Zero 2035 cell has been corrected from 290 to 294. The remaining cells are chart-read and are flagged.
